Workbook

Sheet Sunglasses BOM
A1: PO DATE | B1: PO NO | C1: Part # | D1: Description | E1: Quantity | F1: Body Material | G1: Lens Material | H1: Lens Mono/2Tone/Mirror/Tinted | I1: Lens Colour | J1: Frame Inside Color | K1: Temple Inside Color | L1: Fraame Outside Color | M1: Temple Outside Colour | N1: Rivet Material | O1: Screw Material | P1: Frame Width | Q1: Frame height | R1: Temple Length | S1: Lens width | T1: Lens Height | U1: Weight +-2% | V1: Frame Inside Pantone | W1: Temple inside Pantone | X1: Frame Outside Pantone | Y1: Temple Outside Pantone | Z1: Rubberised
B2: ABS | D2: Sunglasses | E2: =E12+E19+E29+E36+E43 -> 1058400 | F2: =E2/23760 -> 44.545455
B3: PP | D3: Sunglasses | E3: =E54+E63+E69+E73+E77 -> 747600 | F3: =E3/23760 -> 31.464646
B4: TOTAL | D4: Sunglasses | E4: =SUM(E2:E3) -> 1806000
A7: 45907 | B7: 1155928 | C7: 6223 BLK | D7: Sunglass, 6223 Black | E7: 100800 | F7: ABS | G7: PC | H7: Monotone | I7: Black | K7: Black | L7: Black | N7: Zinc Alloy | O7: Stainless Steel | P7: 145.6 mm | Q7: 49 mm | R7: 156 mm | S7: 52.7 mm | T7: 43.8 mm | U7: 19.6 gm | V7: Black 6C | W7: Black 6C | X7: Black 6C | Y7: Black 6C
C8: 6223 NAV | D8: Sunglass, 6223 Navy | E8: 50400 | F8: ABS | G8: PC | H8: Monotone | I8: Black | K8: Navy | L8: Navy | N8: Zinc Alloy | O8: Stainless Steel | P8: 145.6 mm | Q8: 49 mm | R8: 156 mm | S8: 52.7 mm | T8: 43.8 mm | U8: 19.6 gm | V8: 648C | W8: 648C | X8: 648C | Y8: 648C
C9: 6223 RED | D9: Sunglass, 6223 Red | E9: 50400 | F9: ABS | G9: PC | H9: Monotone | I9: Black | K9: Red | L9: Red | N9: Zinc Alloy | O9: Stainless Steel | P9: 145.6 mm | Q9: 49 mm | R9: 156 mm | S9: 52.7 mm | T9: 43.8 mm | U9: 19.6 gm | V9: 1807C | W9: 1807C | X9: 1807C | Y9: 1807C
C10: 6223 ROY | D10: Sunglass, 6223 Royal | E10: 50400 | F10: ABS | G10: PC | H10: Monotone | I10: Black | K10: Royal | L10: Royal | N10: Zinc Alloy | O10: Stainless Steel | P10: 145.6 mm | Q10: 49 mm | R10: 156 mm | S10: 52.7 mm | T10: 43.8 mm | U10: 19.6 gm | V10: 2746C | W10: 2746C | X10: 2746C | Y10: 2746C
C11: 6223 WHT | D11: Sunglass, 6223 White | E11: 100800 | F11: ABS | G11: PC | H11: Monotone | I11: Black | K11: White | L11: White | N11: Zinc Alloy | O11: Stainless Steel | P11: 145.6 mm | Q11: 49 mm | R11: 156 mm | S11: 52.7 mm | T11: 43.8 mm | U11: 19.6 gm | V11: WHITE | W11: WHITE | X11: WHITE | Y11: WHITE
E12: =SUM(E7:E11) -> 352800
A14: 14-07-2025 | B14: 1159052 | C14: 6223 BLK | D14: Sunglass, 6223 Black | E14: 117600 | F14: ABS | G14: PC | H14: Monotone | I14: Black | K14: Black | L14: Black | N14: Zinc Alloy | O14: Stainless Steel | P14: 145.6 mm | Q14: 49 mm | R14: 156 mm | S14: 52.7 mm | T14: 43.8 mm | U14: 19.6 gm | V14: Black 6C | W14: Black 6C | X14: Black 6C | Y14: Black 6C
C15: 6223 NAV | D15: Sunglass, 6223 Navy | E15: 50400 | F15: ABS | G15: PC | H15: Monotone | I15: Black | K15: Navy | L15: Navy | N15: Zinc Alloy | O15: Stainless Steel | P15: 145.6 mm | Q15: 49 mm | R15: 156 mm | S15: 52.7 mm | T15: 43.8 mm | U15: 19.6 gm | V15: 648C | W15: 648C | X15: 648C | Y15: 648C
C16: 6223 RED | D16: Sunglass, 6223 Red | E16: 100800 | F16: ABS | G16: PC | H16: Monotone | I16: Black | K16: Red | L16: Red | N16: Zinc Alloy | O16: Stainless Steel | P16: 145.6 mm | Q16: 49 mm | R16: 156 mm | S16: 52.7 mm | T16: 43.8 mm | U16: 19.6 gm | V16: 1807C | W16: 1807C | X16: 1807C | Y16: 1807C
C17: 6223 ROY | D17: Sunglass, 6223 Royal | E17: 50400 | F17: ABS | G17: PC | H17: Monotone | I17: Black | K17: Royal | L17: Royal | N17: Zinc Alloy | O17: Stainless Steel | P17: 145.6 mm | Q17: 49 mm | R17: 156 mm | S17: 52.7 mm | T17: 43.8 mm | U17: 19.6 gm | V17: 2746C | W17: 2746C | X17: 2746C | Y17: 2746C
C18: 6223 WHT | D18: Sunglass, 6223 White | E18: 33600 | F18: ABS | G18: PC | H18: Monotone | I18: Black | K18: White | L18: White | N18: Zinc Alloy | O18: Stainless Steel | P18: 145.6 mm | Q18: 49 mm | R18: 156 mm | S18: 52.7 mm | T18: 43.8 mm | U18: 19.6 gm | V18: WHITE | W18: WHITE | X18: WHITE | Y18: WHITE
E19: =SUM(E14:E18) -> 352800
A21: 16-07-2025 | B21: 1160644 | C21: 6224 BLUBLK | D21: Sunglass, 6224 2tone BlueBlack | E21: 33600 | F21: ABS | G21: PC | H21: Monotone | I21: Black | J21: Blue | K21: Blue | L21: Black | M21: Black | N21: Zinc Alloy | O21: Stainless Steel | P21: 145.6 mm | Q21: 49 mm | R21: 156 mm | S21: 52.7 mm | T21: 43.8 mm | U21: 19.6 gm | V21: 2187C | W21: 2187C | X21: Black 6C | Y21: Black 6C
C22: 6224 BLUWHT | D22: Sunglass, 6224 2tone Bluewhite | E22: 16800 | F22: ABS | G22: PC | H22: Monotone | I22: Black | J22: Blue | K22: Blue | L22: White | M22: White | N22: Zinc Alloy | O22: Stainless Steel | P22: 145.6 mm | Q22: 49 mm | R22: 156 mm | S22: 52.7 mm | T22: 43.8 mm | U22: 19.6 gm | V22: 2187C | W22: 2187C | X22: White | Y22: White
C23: 6224 LIMBLK | D23: Sunglass, 6224 2tone limeblack | E23: 25200 | F23: ABS | G23: PC | H23: Monotone | I23: Black | J23: Lime | K23: Lime | L23: Black | M23: Black | N23: Zinc Alloy | O23: Stainless Steel | P23: 145.6 mm | Q23: 49 mm | R23: 156 mm | S23: 52.7 mm | T23: 43.8 mm | U23: 19.6 gm | V23: 368C | W23: 368C | X23: Black 6C | Y23: Black 6C
C24: 6224 ORNBLK | D24: Sunglass, 6224 2tone orangeblack | E24: 16800 | F24: ABS | G24: PC | H24: Monotone | I24: Black | J24: Orange | K24: Orange | L24: Black | M24: Black | N24: Zinc Alloy | O24: Stainless Steel | P24: 145.6 mm | Q24: 49 mm | R24: 156 mm | S24: 52.7 mm | T24: 43.8 mm | U24: 19.6 gm | V24: 1655C | W24: 1655C | X24: Black 6C | Y24: Black 6C
C25: 6224 ORNWHT | D25: Sunglass, 6224 2tone orangewhite | E25: 8400 | F25: ABS | G25: PC | H25: Monotone | I25: Black | J25: Orange | K25: Orange | L25: White | M25: White | N25: Zinc Alloy | O25: Stainless Steel | P25: 145.6 mm | Q25: 49 mm | R25: 156 mm | S25: 52.7 mm | T25: 43.8 mm | U25: 19.6 gm | V25: 1655C | W25: 1655C | X25: White | Y25: White
C26: 6224 REDBLK | D26: Sunglass, 6224 2tone redblack | E26: 25200 | F26: ABS | G26: PC | H26: Monotone | I26: Black | J26: Red | K26: Red | L26: Black | M26: Black | N26: Zinc Alloy | O26: Stainless Steel | P26: 145.6 mm | Q26: 49 mm | R26: 156 mm | S26: 52.7 mm | T26: 43.8 mm | U26: 19.6 gm | V26: 201C | W26: 201C | X26: Black 6C | Y26: Black 6C
C27: 6224 REDWHT | D27: Sunglass, 6224 2tone redwhite | E27: 8400 | F27: ABS | G27: PC | H27: Monotone | I27: Black | J27: Red | K27: Red | L27: White | M27: White | N27: Zinc Alloy | O27: Stainless Steel | P27: 145.6 mm | Q27: 49 mm | R27: 156 mm | S27: 52.7 mm | T27: 43.8 mm | U27: 19.6 gm | V27: 201C | W27: 201C | X27: White | Y27: White
C28: 6224 YELBLK | D28: Sunglass, 6224 2tone yellowblack | E28: 8400 | F28: ABS | G28: PC | H28: Monotone | I28: Black | J28: Yellow | K28: Yellow | L28: Black | M28: Black | N28: Zinc Alloy | O28: Stainless Steel | P28: 145.6 mm | Q28: 49 mm | R28: 156 mm | S28: 52.7 mm | T28: 43.8 mm | U28: 19.6 gm | V28: 107C | W28: 107C | X28: Black 6C | Y28: Black 6C
E29: =SUM(E21:E28) -> 142800
A31: 16-07-2025 | B31: 1160645 | C31: 6207CLRBLU | D31: Sunglass, Clear W/Blue Lenses | E31: 42000 | F31: Clear ABS | G31: PC | H31: Monotone | I31: Blue | K31: Clear | L31: Clear | N31: Zinc Alloy | O31: Stainless Steel | P31: 145.6 mm | Q31: 49 mm | R31: 156 mm | S31: 52.7 mm | T31: 43.8 mm | U31: 19.6 gm | V31: Clear | W31: Clear | X31: Clear | Y31: Clear
C32: 6207CLRGRN | D32: Sunglass, Clear W/Green Lenses | E32: 25200 | F32: Clear ABS | G32: PC | H32: Monotone | I32: Green | K32: Clear | L32: Clear | N32: Zinc Alloy | O32: Stainless Steel | P32: 145.6 mm | Q32: 49 mm | R32: 156 mm | S32: 52.7 mm | T32: 43.8 mm | U32: 19.6 gm | V32: Clear | W32: Clear | X32: Clear | Y32: Clear
C33: 6207CLRRED | D33: Sunglass, Clear W/Red Lenses | E33: 16800 | F33: Clear ABS | G33: PC | H33: Monotone | I33: Red | K33: Clear | L33: Clear | N33: Zinc Alloy | O33: Stainless Steel | P33: 145.6 mm | Q33: 49 mm | R33: 156 mm | S33: 52.7 mm | T33: 43.8 mm | U33: 19.6 gm | V33: Clear | W33: Clear | X33: Clear | Y33: Clear
C34: 6207CLRSIL | D34: Sunglass, Clear W/Silver Lenses | E34: 16800 | F34: Clear ABS | G34: PC | H34: Monotone | I34: Silver | K34: Clear | L34: Clear | N34: Zinc Alloy | O34: Stainless Steel | P34: 145.6 mm | Q34: 49 mm | R34: 156 mm | S34: 52.7 mm | T34: 43.8 mm | U34: 19.6 gm | V34: Clear | W34: Clear | X34: Clear | Y34: Clear
C35: 6207CLRYEL | D35: Sunglass, Clear W/Yellow Lenses | E35: 16800 | F35: Clear ABS | G35: PC | H35: Monotone | I35: Yellow | K35: Clear | L35: Clear | N35: Zinc Alloy | O35: Stainless Steel | P35: 145.6 mm | Q35: 49 mm | R35: 156 mm | S35: 52.7 mm | T35: 43.8 mm | U35: 19.6 gm | V35: Clear | W35: Clear | X35: Clear | Y35: Clear
E36: =SUM(E31:E35) -> 117600
A38: 16-07-2025 | B38: 1160647 | C38: 6223BRTYEL | D38: Sunglass, 6223, Bright Yellow | E38: 16800 | F38: ABS | G38: PC | H38: Monotone | I38: Black | K38: Bright Yellow | L38: Bright Yellow | N38: Zinc Alloy | O38: Stainless Steel | P38: 145.6 mm | Q38: 49 mm | R38: 156 mm | S38: 52.7 mm | T38: 43.8 mm | U38: 19.6 gm | V38: 7405C | W38: 7405C | X38: 7405C | Y38: 7405C
C39: 6223CBL | D39: Sunglass, 6223, Light Blue | E39: 25200 | F39: ABS | G39: PC | H39: Monotone | I39: Black | K39: Light Blue | L39: Light Blue | N39: Zinc Alloy | O39: Stainless Steel | P39: 145.6 mm | Q39: 49 mm | R39: 156 mm | S39: 52.7 mm | T39: 43.8 mm | U39: 19.6 gm | V39: 14-4318 TCX | W39: 14-4318 TCX | X39: 14-4318 TCX | Y39: 14-4318 TCX
C40: 6223GRA | D40: Sunglass, 6223, Gray | E40: 16800 | F40: ABS | G40: PC | H40: Monotone | I40: Black | K40: Gray | L40: Gray | N40: Zinc Alloy | O40: Stainless Steel | P40: 145.6 mm | Q40: 49 mm | R40: 156 mm | S40: 52.7 mm | T40: 43.8 mm | U40: 19.6 gm | V40: Cool Gray 8C | W40: Cool Gray 8C | X40: Cool Gray 8C | Y40: Cool Gray 8C
C41: 6223GRK | D41: Sunglass, 6223, Kelly Green | E41: 16800 | F41: ABS | G41: PC | H41: Monotone | I41: Black | K41: Kelly Green | L41: Kelly Green | N41: Zinc Alloy | O41: Stainless Steel | P41: 145.6 mm | Q41: 49 mm | R41: 156 mm | S41: 52.7 mm | T41: 43.8 mm | U41: 19.6 gm | V41: 342C | W41: 342C | X41: 342C | Y41: 342C
C42: 6223PUR | D42: Sunglass, 6223, Purple | E42: 16800 | F42: ABS | G42: PC | H42: Monotone | I42: Black | K42: Purple | L42: Purple | N42: Zinc Alloy | O42: Stainless Steel | P42: 145.6 mm | Q42: 49 mm | R42: 156 mm | S42: 52.7 mm | T42: 43.8 mm | U42: 19.6 gm | V42: 2077C | W42: 2077C | X42: 2077C | Y42: 2077C
E43: =SUM(E38:E42) -> 92400
A45: 21-07-2025 | B45: 1163004 | C45: 4000 BLK | D45: Sunglass, Black Frame, Black Temple | E45: 117600 | F45: PP | G45: PC | H45: Monotone | I45: Black | K45: Black | L45: Black | O45: Stainless Steel | P45: 140 mm | Q45: 48.5 mm | R45: 153 mm | S45: 53.5 mm | T45: 44 mm | U45: 20.15 gm | V45: Black C | W45: Black C | X45: Black C | Y45: Black C
C46: 4000 BLU | D46: Sunglass, Rubberised Blue | E46: 58800 | F46: PP | G46: PC | H46: Monotone | I46: Black | K46: Blue | L46: Blue | O46: Stainless Steel | P46: 140 mm | Q46: 48.5 mm | R46: 153 mm | S46: 53.5 mm | T46: 44 mm | U46: 20.15 gm | V46: 2144C | W46: 2144C | X46: 2144C | Y46: 2144C | Z46: Rubberised
C47: 4000 BLUBLU | D47: Sunglass, Blue Frame, Blue Temple | E47: 50400 | F47: PP | G47: PC | H47: Monotone | I47: Black | K47: Blue | L47: Blue | O47: Stainless Steel | P47: 140 mm | Q47: 48.5 mm | R47: 153 mm | S47: 53.5 mm | T47: 44 mm | U47: 20.15 gm | V47: 2144C | W47: 2144C | X47: 2144C | Y47: 2144C
...

Sheet Raw Material Requirement
A1: Raw Material Requirement
A3: Pantone Code | B3: Color | C3: Temple Quantity (ABS) | D3: Frame Quantity (ABS) | E3: Temple Weight - Each (Gm) | F3: Frame Weight (Gm) | G3: ABS Requirement (kg) | H3: ABS Masterbatch (kg) | I3: Temple Quantity (Clear ABS) | J3: Frame Quantity (Clear ABS) | K3: Clear ABS Requirement (kg) | L3: Temple Weight - Each (Gm) | M3: Frame Weight (Gm) | N3: Temple Quantity (PP) | O3: Frame Quantity (PP) | P3: PP Requirement (kg) | Q3: PP Masterbatch requirement (kg) | R3: Rubberised paint required (kg)
A4: Black 6C | B4: =_xlfn.XLOOKUP(A4,'Sunglasses BOM'!$W$7:$W$76,'Sunglasses BOM'!$K$7:$K$76) -> Black | C4: =IFERROR(2*SUMIFS('Sunglasses BOM'!$E:$E, 'Sunglasses BOM'!$F:$F,"ABS", 'Sunglasses BOM'!$W:$W,$A4),0) -> 436800 | D4: =IFERROR(SUMIFS('Sunglasses BOM'!$E:$E, 'Sunglasses BOM'!$F:$F,"ABS", 'Sunglasses BOM'!$V:$V,$A4),0) -> 218400 | E4: 3.8 | F4: 6.4 | G4: =((F4*D4)+(E4*C4))/1000 -> 3057.6 | H4: =G4*0.02 -> 61.152 | I4: =IFERROR(2*SUMIFS('Sunglasses BOM'!$E:$E, 'Sunglasses BOM'!$F:$F,"Clear ABS", 'Sunglasses BOM'!$W:$W,$A4),0) -> 0 | J4: =IFERROR(SUMIFS('Sunglasses BOM'!$E:$E, 'Sunglasses BOM'!$F:$F,"Clear ABS", 'Sunglasses BOM'!$V:$V,$A4),0) -> 0 | K4: =(J4*F4)+(I4*E4) -> 0 | L4: 2.95 | M4: 7.4 | N4: =IFERROR(2*SUMIFS('Sunglasses BOM'!$E:$E, 'Sunglasses BOM'!$F:$F,"PP", 'Sunglasses BOM'!$W:$W,$A4),0) -> 0 | O4: =IFERROR(SUMIFS('Sunglasses BOM'!$E:$E, 'Sunglasses BOM'!$F:$F,"PP", 'Sunglasses BOM'!$V:$V,$A4),0) -> 0 | P4: =((O4*M4)+(N4*L4))/1000 -> 0 | Q4: =P4*0.02 -> 0
A5: 648C | B5: =_xlfn.XLOOKUP(A5,'Sunglasses BOM'!$W$7:$W$76,'Sunglasses BOM'!$K$7:$K$76) -> Navy | C5: =IFERROR(2*SUMIFS('Sunglasses BOM'!$E:$E, 'Sunglasses BOM'!$F:$F,"ABS", 'Sunglasses BOM'!$W:$W,$A5),0) -> 201600 | D5: =IFERROR(SUMIFS('Sunglasses BOM'!$E:$E, 'Sunglasses BOM'!$F:$F,"ABS", 'Sunglasses BOM'!$V:$V,$A5),0) -> 100800 | E5: 3.8 | F5: 6.4 | G5: =((F5*D5)+(E5*C5))/1000 -> 1411.2 | H5: =G5*0.02 -> 28.224 | I5: =IFERROR(2*SUMIFS('Sunglasses BOM'!$E:$E, 'Sunglasses BOM'!$F:$F,"Clear ABS", 'Sunglasses BOM'!$W:$W,$A5),0) -> 0 | J5: =IFERROR(SUMIFS('Sunglasses BOM'!$E:$E, 'Sunglasses BOM'!$F:$F,"Clear ABS", 'Sunglasses BOM'!$V:$V,$A5),0) -> 0 | K5: =(J5*F5)+(I5*E5) -> 0 | L5: 2.95 | M5: 7.4 | N5: =IFERROR(2*SUMIFS('Sunglasses BOM'!$E:$E, 'Sunglasses BOM'!$F:$F,"PP", 'Sunglasses BOM'!$W:$W,$A5),0) -> 0 | O5: =IFERROR(SUMIFS('Sunglasses BOM'!$E:$E, 'Sunglasses BOM'!$F:$F,"PP", 'Sunglasses BOM'!$V:$V,$A5),0) -> 0 | P5: =((O5*M5)+(N5*L5))/1000 -> 0 | Q5: =P5*0.02 -> 0
A6: 1807C | B6: =_xlfn.XLOOKUP(A6,'Sunglasses BOM'!$W$7:$W$76,'Sunglasses BOM'!$K$7:$K$76) -> Red | C6: =IFERROR(2*SUMIFS('Sunglasses BOM'!$E:$E, 'Sunglasses BOM'!$F:$F,"ABS", 'Sunglasses BOM'!$W:$W,$A6),0) -> 302400 | D6: =IFERROR(SUMIFS('Sunglasses BOM'!$E:$E, 'Sunglasses BOM'!$F:$F,"ABS", 'Sunglasses BOM'!$V:$V,$A6),0) -> 151200 | E6: 3.8 | F6: 6.4 | G6: =((F6*D6)+(E6*C6))/1000 -> 2116.8 | H6: =G6*0.02 -> 42.336 | I6: =IFERROR(2*SUMIFS('Sunglasses BOM'!$E:$E, 'Sunglasses BOM'!$F:$F,"Clear ABS", 'Sunglasses BOM'!$W:$W,$A6),0) -> 0 | J6: =IFERROR(SUMIFS('Sunglasses BOM'!$E:$E, 'Sunglasses BOM'!$F:$F,"Clear ABS", 'Sunglasses BOM'!$V:$V,$A6),0) -> 0 | K6: =(J6*F6)+(I6*E6) -> 0 | L6: 2.95 | M6: 7.4 | N6: =IFERROR(2*SUMIFS('Sunglasses BOM'!$E:$E, 'Sunglasses BOM'!$F:$F,"PP", 'Sunglasses BOM'!$W:$W,$A6),0) -> 0 | O6: =IFERROR(SUMIFS('Sunglasses BOM'!$E:$E, 'Sunglasses BOM'!$F:$F,"PP", 'Sunglasses BOM'!$V:$V,$A6),0) -> 0 | P6: =((O6*M6)+(N6*L6))/1000 -> 0 | Q6: =P6*0.02 -> 0
A7: 2746C | B7: =_xlfn.XLOOKUP(A7,'Sunglasses BOM'!$W$7:$W$76,'Sunglasses BOM'!$K$7:$K$76) -> Royal | C7: =IFERROR(2*SUMIFS('Sunglasses BOM'!$E:$E, 'Sunglasses BOM'!$F:$F,"ABS", 'Sunglasses BOM'!$W:$W,$A7),0) -> 201600 | D7: =IFERROR(SUMIFS('Sunglasses BOM'!$E:$E, 'Sunglasses BOM'!$F:$F,"ABS", 'Sunglasses BOM'!$V:$V,$A7),0) -> 100800 | E7: 3.8 | F7: 6.4 | G7: =((F7*D7)+(E7*C7))/1000 -> 1411.2 | H7: =G7*0.02 -> 28.224 | I7: =IFERROR(2*SUMIFS('Sunglasses BOM'!$E:$E, 'Sunglasses BOM'!$F:$F,"Clear ABS", 'Sunglasses BOM'!$W:$W,$A7),0) -> 0 | J7: =IFERROR(SUMIFS('Sunglasses BOM'!$E:$E, 'Sunglasses BOM'!$F:$F,"Clear ABS", 'Sunglasses BOM'!$V:$V,$A7),0) -> 0 | K7: =(J7*F7)+(I7*E7) -> 0 | L7: 2.95 | M7: 7.4 | N7: =IFERROR(2*SUMIFS('Sunglasses BOM'!$E:$E, 'Sunglasses BOM'!$F:$F,"PP", 'Sunglasses BOM'!$W:$W,$A7),0) -> 0 | O7: =IFERROR(SUMIFS('Sunglasses BOM'!$E:$E, 'Sunglasses BOM'!$F:$F,"PP", 'Sunglasses BOM'!$V:$V,$A7),0) -> 0 | P7: =((O7*M7)+(N7*L7))/1000 -> 0 | Q7: =P7*0.02 -> 0
A8: WHITE | B8: =_xlfn.XLOOKUP(A8,'Sunglasses BOM'!$W$7:$W$76,'Sunglasses BOM'!$K$7:$K$76) -> White | C8: =IFERROR(2*SUMIFS('Sunglasses BOM'!$E:$E, 'Sunglasses BOM'!$F:$F,"ABS", 'Sunglasses BOM'!$W:$W,$A8),0) -> 268800 | D8: =IFERROR(SUMIFS('Sunglasses BOM'!$E:$E, 'Sunglasses BOM'!$F:$F,"ABS", 'Sunglasses BOM'!$V:$V,$A8),0) -> 134400 | E8: 3.8 | F8: 6.4 | G8: =((F8*D8)+(E8*C8))/1000 -> 1881.6 | H8: =G8*0.02 -> 37.632 | I8: =IFERROR(2*SUMIFS('Sunglasses BOM'!$E:$E, 'Sunglasses BOM'!$F:$F,"Clear ABS", 'Sunglasses BOM'!$W:$W,$A8),0) -> 0 | J8: =IFERROR(SUMIFS('Sunglasses BOM'!$E:$E, 'Sunglasses BOM'!$F:$F,"Clear ABS", 'Sunglasses BOM'!$V:$V,$A8),0) -> 0 | K8: =(J8*F8)+(I8*E8) -> 0 | L8: 2.95 | M8: 7.4 | N8: =IFERROR(2*SUMIFS('Sunglasses BOM'!$E:$E, 'Sunglasses BOM'!$F:$F,"PP", 'Sunglasses BOM'!$W:$W,$A8),0) -> 403200 | O8: =IFERROR(SUMIFS('Sunglasses BOM'!$E:$E, 'Sunglasses BOM'!$F:$F,"PP", 'Sunglasses BOM'!$V:$V,$A8),0) -> 252000 | P8: =((O8*M8)+(N8*L8))/1000 -> 3054.24 | Q8: =P8*0.02 -> 61.0848
A9: 2187C | B9: =_xlfn.XLOOKUP(A9,'Sunglasses BOM'!$W$7:$W$76,'Sunglasses BOM'!$K$7:$K$76) -> Blue | C9: =IFERROR(2*SUMIFS('Sunglasses BOM'!$E:$E, 'Sunglasses BOM'!$F:$F,"ABS", 'Sunglasses BOM'!$W:$W,$A9),0) -> 100800 | D9: =IFERROR(SUMIFS('Sunglasses BOM'!$E:$E, 'Sunglasses BOM'!$F:$F,"ABS", 'Sunglasses BOM'!$V:$V,$A9),0) -> 50400 | E9: 3.8 | F9: 6.4 | G9: =((F9*D9)+(E9*C9))/1000 -> 705.6 | H9: =G9*0.02 -> 14.112 | I9: =IFERROR(2*SUMIFS('Sunglasses BOM'!$E:$E, 'Sunglasses BOM'!$F:$F,"Clear ABS", 'Sunglasses BOM'!$W:$W,$A9),0) -> 0 | J9: =IFERROR(SUMIFS('Sunglasses BOM'!$E:$E, 'Sunglasses BOM'!$F:$F,"Clear ABS", 'Sunglasses BOM'!$V:$V,$A9),0) -> 0 | K9: =(J9*F9)+(I9*E9) -> 0 | L9: 2.95 | M9: 7.4 | N9: =IFERROR(2*SUMIFS('Sunglasses BOM'!$E:$E, 'Sunglasses BOM'!$F:$F,"PP", 'Sunglasses BOM'!$W:$W,$A9),0) -> 0 | O9: =IFERROR(SUMIFS('Sunglasses BOM'!$E:$E, 'Sunglasses BOM'!$F:$F,"PP", 'Sunglasses BOM'!$V:$V,$A9),0) -> 0 | P9: =((O9*M9)+(N9*L9))/1000 -> 0 | Q9: =P9*0.02 -> 0
A10: 368C | B10: =_xlfn.XLOOKUP(A10,'Sunglasses BOM'!$W$7:$W$76,'Sunglasses BOM'!$K$7:$K$76) -> Lime | C10: =IFERROR(2*SUMIFS('Sunglasses BOM'!$E:$E, 'Sunglasses BOM'!$F:$F,"ABS", 'Sunglasses BOM'!$W:$W,$A10),0) -> 50400 | D10: =IFERROR(SUMIFS('Sunglasses BOM'!$E:$E, 'Sunglasses BOM'!$F:$F,"ABS", 'Sunglasses BOM'!$V:$V,$A10),0) -> 25200 | E10: 3.8 | F10: 6.4 | G10: =((F10*D10)+(E10*C10))/1000 -> 352.8 | H10: =G10*0.02 -> 7.056 | I10: =IFERROR(2*SUMIFS('Sunglasses BOM'!$E:$E, 'Sunglasses BOM'!$F:$F,"Clear ABS", 'Sunglasses BOM'!$W:$W,$A10),0) -> 0 | J10: =IFERROR(SUMIFS('Sunglasses BOM'!$E:$E, 'Sunglasses BOM'!$F:$F,"Clear ABS", 'Sunglasses BOM'!$V:$V,$A10),0) -> 0 | K10: =(J10*F10)+(I10*E10) -> 0 | L10: 2.95 | M10: 7.4 | N10: =IFERROR(2*SUMIFS('Sunglasses BOM'!$E:$E, 'Sunglasses BOM'!$F:$F,"PP", 'Sunglasses BOM'!$W:$W,$A10),0) -> 0 | O10: =IFERROR(SUMIFS('Sunglasses BOM'!$E:$E, 'Sunglasses BOM'!$F:$F,"PP", 'Sunglasses BOM'!$V:$V,$A10),0) -> 0 | P10: =((O10*M10)+(N10*L10))/1000 -> 0 | Q10: =P10*0.02 -> 0
A11: 1655C | B11: =_xlfn.XLOOKUP(A11,'Sunglasses BOM'!$W$7:$W$76,'Sunglasses BOM'!$K$7:$K$76) -> Orange | C11: =IFERROR(2*SUMIFS('Sunglasses BOM'!$E:$E, 'Sunglasses BOM'!$F:$F,"ABS", 'Sunglasses BOM'!$W:$W,$A11),0) -> 50400 | D11: =IFERROR(SUMIFS('Sunglasses BOM'!$E:$E, 'Sunglasses BOM'!$F:$F,"ABS", 'Sunglasses BOM'!$V:$V,$A11),0) -> 25200 | E11: 3.8 | F11: 6.4 | G11: =((F11*D11)+(E11*C11))/1000 -> 352.8 | H11: =G11*0.02 -> 7.056 | I11: =IFERROR(2*SUMIFS('Sunglasses BOM'!$E:$E, 'Sunglasses BOM'!$F:$F,"Clear ABS", 'Sunglasses BOM'!$W:$W,$A11),0) -> 0 | J11: =IFERROR(SUMIFS('Sunglasses BOM'!$E:$E, 'Sunglasses BOM'!$F:$F,"Clear ABS", 'Sunglasses BOM'!$V:$V,$A11),0) -> 0 | K11: =(J11*F11)+(I11*E11) -> 0 | L11: 2.95 | M11: 7.4 | N11: =IFERROR(2*SUMIFS('Sunglasses BOM'!$E:$E, 'Sunglasses BOM'!$F:$F,"PP", 'Sunglasses BOM'!$W:$W,$A11),0) -> 0 | O11: =IFERROR(SUMIFS('Sunglasses BOM'!$E:$E, 'Sunglasses BOM'!$F:$F,"PP", 'Sunglasses BOM'!$V:$V,$A11),0) -> 0 | P11: =((O11*M11)+(N11*L11))/1000 -> 0 | Q11: =P11*0.02 -> 0
A12: 201C | B12: =_xlfn.XLOOKUP(A12,'Sunglasses BOM'!$W$7:$W$76,'Sunglasses BOM'!$K$7:$K$76) -> Red | C12: =IFERROR(2*SUMIFS('Sunglasses BOM'!$E:$E, 'Sunglasses BOM'!$F:$F,"ABS", 'Sunglasses BOM'!$W:$W,$A12),0) -> 67200 | D12: =IFERROR(SUMIFS('Sunglasses BOM'!$E:$E, 'Sunglasses BOM'!$F:$F,"ABS", 'Sunglasses BOM'!$V:$V,$A12),0) -> 33600 | E12: 3.8 | F12: 6.4 | G12: =((F12*D12)+(E12*C12))/1000 -> 470.4 | H12: =G12*0.02 -> 9.408 | I12: =IFERROR(2*SUMIFS('Sunglasses BOM'!$E:$E, 'Sunglasses BOM'!$F:$F,"Clear ABS", 'Sunglasses BOM'!$W:$W,$A12),0) -> 0 | J12: =IFERROR(SUMIFS('Sunglasses BOM'!$E:$E, 'Sunglasses BOM'!$F:$F,"Clear ABS", 'Sunglasses BOM'!$V:$V,$A12),0) -> 0 | K12: =(J12*F12)+(I12*E12) -> 0 | L12: 2.95 | M12: 7.4 | N12: =IFERROR(2*SUMIFS('Sunglasses BOM'!$E:$E, 'Sunglasses BOM'!$F:$F,"PP", 'Sunglasses BOM'!$W:$W,$A12),0) -> 0 | O12: =IFERROR(SUMIFS('Sunglasses BOM'!$E:$E, 'Sunglasses BOM'!$F:$F,"PP", 'Sunglasses BOM'!$V:$V,$A12),0) -> 0 | P12: =((O12*M12)+(N12*L12))/1000 -> 0 | Q12: =P12*0.02 -> 0
A13: 107C | B13: =_xlfn.XLOOKUP(A13,'Sunglasses BOM'!$W$7:$W$76,'Sunglasses BOM'!$K$7:$K$76) -> Yellow | C13: =IFERROR(2*SUMIFS('Sunglasses BOM'!$E:$E, 'Sunglasses BOM'!$F:$F,"ABS", 'Sunglasses BOM'!$W:$W,$A13),0) -> 16800 | D13: =IFERROR(SUMIFS('Sunglasses BOM'!$E:$E, 'Sunglasses BOM'!$F:$F,"ABS", 'Sunglasses BOM'!$V:$V,$A13),0) -> 8400 | E13: 3.8 | F13: 6.4 | G13: =((F13*D13)+(E13*C13))/1000 -> 117.6 | H13: =G13*0.02 -> 2.352 | I13: =IFERROR(2*SUMIFS('Sunglasses BOM'!$E:$E, 'Sunglasses BOM'!$F:$F,"Clear ABS", 'Sunglasses BOM'!$W:$W,$A13),0) -> 0 | J13: =IFERROR(SUMIFS('Sunglasses BOM'!$E:$E, 'Sunglasses BOM'!$F:$F,"Clear ABS", 'Sunglasses BOM'!$V:$V,$A13),0) -> 0 | K13: =(J13*F13)+(I13*E13) -> 0 | L13: 2.95 | M13: 7.4 | N13: =IFERROR(2*SUMIFS('Sunglasses BOM'!$E:$E, 'Sunglasses BOM'!$F:$F,"PP", 'Sunglasses BOM'!$W:$W,$A13),0) -> 0 | O13: =IFERROR(SUMIFS('Sunglasses BOM'!$E:$E, 'Sunglasses BOM'!$F:$F,"PP", 'Sunglasses BOM'!$V:$V,$A13),0) -> 0 | P13: =((O13*M13)+(N13*L13))/1000 -> 0 | Q13: =P13*0.02 -> 0
A14: Clear | B14: =_xlfn.XLOOKUP(A14,'Sunglasses BOM'!$W$7:$W$76,'Sunglasses BOM'!$K$7:$K$76) -> Clear | C14: =IFERROR(2*SUMIFS('Sunglasses BOM'!$E:$E, 'Sunglasses BOM'!$F:$F,"ABS", 'Sunglasses BOM'!$W:$W,$A14),0) -> 0 | D14: =IFERROR(SUMIFS('Sunglasses BOM'!$E:$E, 'Sunglasses BOM'!$F:$F,"ABS", 'Sunglasses BOM'!$V:$V,$A14),0) -> 0 | E14: 3.8 | F14: 6.4 | G14: =((F14*D14)+(E14*C14))/1000 -> 0 | H14: =G14*0.02 -> 0 | I14: =IFERROR(2*SUMIFS('Sunglasses BOM'!$E:$E, 'Sunglasses BOM'!$F:$F,"Clear ABS", 'Sunglasses BOM'!$W:$W,$A14),0) -> 235200 | J14: =IFERROR(SUMIFS('Sunglasses BOM'!$E:$E, 'Sunglasses BOM'!$F:$F,"Clear ABS", 'Sunglasses BOM'!$V:$V,$A14),0) -> 117600 | K14: =((J14*F14)+(I14*E14))/1000 -> 1646.4 | L14: 2.95 | M14: 7.4 | N14: =IFERROR(2*SUMIFS('Sunglasses BOM'!$E:$E, 'Sunglasses BOM'!$F:$F,"PP", 'Sunglasses BOM'!$W:$W,$A14),0) -> 0 | O14: =IFERROR(SUMIFS('Sunglasses BOM'!$E:$E, 'Sunglasses BOM'!$F:$F,"PP", 'Sunglasses BOM'!$V:$V,$A14),0) -> 0 | P14: =((O14*M14)+(N14*L14))/1000 -> 0 | Q14: =P14*0.02 -> 0
A15: 7405C | B15: =_xlfn.XLOOKUP(A15,'Sunglasses BOM'!$W$7:$W$76,'Sunglasses BOM'!$K$7:$K$76) -> Bright Yellow | C15: =IFERROR(2*SUMIFS('Sunglasses BOM'!$E:$E, 'Sunglasses BOM'!$F:$F,"ABS", 'Sunglasses BOM'!$W:$W,$A15),0) -> 33600 | D15: =IFERROR(SUMIFS('Sunglasses BOM'!$E:$E, 'Sunglasses BOM'!$F:$F,"ABS", 'Sunglasses BOM'!$V:$V,$A15),0) -> 16800 | E15: 3.8 | F15: 6.4 | G15: =((F15*D15)+(E15*C15))/1000 -> 235.2 | H15: =G15*0.02 -> 4.704 | I15: =IFERROR(2*SUMIFS('Sunglasses BOM'!$E:$E, 'Sunglasses BOM'!$F:$F,"Clear ABS", 'Sunglasses BOM'!$W:$W,$A15),0) -> 0 | J15: =IFERROR(SUMIFS('Sunglasses BOM'!$E:$E, 'Sunglasses BOM'!$F:$F,"Clear ABS", 'Sunglasses BOM'!$V:$V,$A15),0) -> 0 | K15: =(J15*F15)+(I15*E15) -> 0 | L15: 2.95 | M15: 7.4 | N15: =IFERROR(2*SUMIFS('Sunglasses BOM'!$E:$E, 'Sunglasses BOM'!$F:$F,"PP", 'Sunglasses BOM'!$W:$W,$A15),0) -> 0 | O15: =IFERROR(SUMIFS('Sunglasses BOM'!$E:$E, 'Sunglasses BOM'!$F:$F,"PP", 'Sunglasses BOM'!$V:$V,$A15),0) -> 0 | P15: =((O15*M15)+(N15*L15))/1000 -> 0 | Q15: =P15*0.02 -> 0
A16: 14-4318 TCX | B16: =_xlfn.XLOOKUP(A16,'Sunglasses BOM'!$W$7:$W$76,'Sunglasses BOM'!$K$7:$K$76) -> Light Blue | C16: =IFERROR(2*SUMIFS('Sunglasses BOM'!$E:$E, 'Sunglasses BOM'!$F:$F,"ABS", 'Sunglasses BOM'!$W:$W,$A16),0) -> 50400 | D16: =IFERROR(SUMIFS('Sunglasses BOM'!$E:$E, 'Sunglasses BOM'!$F:$F,"ABS", 'Sunglasses BOM'!$V:$V,$A16),0) -> 25200 | E16: 3.8 | F16: 6.4 | G16: =((F16*D16)+(E16*C16))/1000 -> 352.8 | H16: =G16*0.02 -> 7.056 | I16: =IFERROR(2*SUMIFS('Sunglasses BOM'!$E:$E, 'Sunglasses BOM'!$F:$F,"Clear ABS", 'Sunglasses BOM'!$W:$W,$A16),0) -> 0 | J16: =IFERROR(SUMIFS('Sunglasses BOM'!$E:$E, 'Sunglasses BOM'!$F:$F,"Clear ABS", 'Sunglasses BOM'!$V:$V,$A16),0) -> 0 | K16: =(J16*F16)+(I16*E16) -> 0 | L16: 2.95 | M16: 7.4 | N16: =IFERROR(2*SUMIFS('Sunglasses BOM'!$E:$E, 'Sunglasses BOM'!$F:$F,"PP", 'Sunglasses BOM'!$W:$W,$A16),0) -> 0 | O16: =IFERROR(SUMIFS('Sunglasses BOM'!$E:$E, 'Sunglasses BOM'!$F:$F,"PP", 'Sunglasses BOM'!$V:$V,$A16),0) -> 0 | P16: =((O16*M16)+(N16*L16))/1000 -> 0 | Q16: =P16*0.02 -> 0
A17: Cool Gray 8C | B17: =_xlfn.XLOOKUP(A17,'Sunglasses BOM'!$W$7:$W$76,'Sunglasses BOM'!$K$7:$K$76) -> Gray | C17: =IFERROR(2*SUMIFS('Sunglasses BOM'!$E:$E, 'Sunglasses BOM'!$F:$F,"ABS", 'Sunglasses BOM'!$W:$W,$A17),0) -> 33600 | D17: =IFERROR(SUMIFS('Sunglasses BOM'!$E:$E, 'Sunglasses BOM'!$F:$F,"ABS", 'Sunglasses BOM'!$V:$V,$A17),0) -> 16800 | E17: 3.8 | F17: 6.4 | G17: =((F17*D17)+(E17*C17))/1000 -> 235.2 | H17: =G17*0.02 -> 4.704 | I17: =IFERROR(2*SUMIFS('Sunglasses BOM'!$E:$E, 'Sunglasses BOM'!$F:$F,"Clear ABS", 'Sunglasses BOM'!$W:$W,$A17),0) -> 0 | J17: =IFERROR(SUMIFS('Sunglasses BOM'!$E:$E, 'Sunglasses BOM'!$F:$F,"Clear ABS", 'Sunglasses BOM'!$V:$V,$A17),0) -> 0 | K17: =(J17*F17)+(I17*E17) -> 0 | L17: 2.95 | M17: 7.4 | N17: =IFERROR(2*SUMIFS('Sunglasses BOM'!$E:$E, 'Sunglasses BOM'!$F:$F,"PP", 'Sunglasses BOM'!$W:$W,$A17),0) -> 0 | O17: =IFERROR(SUMIFS('Sunglasses BOM'!$E:$E, 'Sunglasses BOM'!$F:$F,"PP", 'Sunglasses BOM'!$V:$V,$A17),0) -> 0 | P17: =((O17*M17)+(N17*L17))/1000 -> 0 | Q17: =P17*0.02 -> 0
A18: 342C | B18: =_xlfn.XLOOKUP(A18,'Sunglasses BOM'!$W$7:$W$76,'Sunglasses BOM'!$K$7:$K$76) -> Kelly Green | C18: =IFERROR(2*SUMIFS('Sunglasses BOM'!$E:$E, 'Sunglasses BOM'!$F:$F,"ABS", 'Sunglasses BOM'!$W:$W,$A18),0) -> 33600 | D18: =IFERROR(SUMIFS('Sunglasses BOM'!$E:$E, 'Sunglasses BOM'!$F:$F,"ABS", 'Sunglasses BOM'!$V:$V,$A18),0) -> 16800 | E18: 3.8 | F18: 6.4 | G18: =((F18*D18)+(E18*C18))/1000 -> 235.2 | H18: =G18*0.02 -> 4.704 | I18: =IFERROR(2*SUMIFS('Sunglasses BOM'!$E:$E, 'Sunglasses BOM'!$F:$F,"Clear ABS", 'Sunglasses BOM'!$W:$W,$A18),0) -> 0 | J18: =IFERROR(SUMIFS('Sunglasses BOM'!$E:$E, 'Sunglasses BOM'!$F:$F,"Clear ABS", 'Sunglasses BOM'!$V:$V,$A18),0) -> 0 | K18: =(J18*F18)+(I18*E18) -> 0 | L18: 2.95 | M18: 7.4 | N18: =IFERROR(2*SUMIFS('Sunglasses BOM'!$E:$E, 'Sunglasses BOM'!$F:$F,"PP", 'Sunglasses BOM'!$W:$W,$A18),0) -> 0 | O18: =IFERROR(SUMIFS('Sunglasses BOM'!$E:$E, 'Sunglasses BOM'!$F:$F,"PP", 'Sunglasses BOM'!$V:$V,$A18),0) -> 0 | P18: =((O18*M18)+(N18*L18))/1000 -> 0 | Q18: =P18*0.02 -> 0
A19: 2077C | B19: =_xlfn.XLOOKUP(A19,'Sunglasses BOM'!$W$7:$W$76,'Sunglasses BOM'!$K$7:$K$76) -> Purple | C19: =IFERROR(2*SUMIFS('Sunglasses BOM'!$E:$E, 'Sunglasses BOM'!$F:$F,"ABS", 'Sunglasses BOM'!$W:$W,$A19),0) -> 33600 | D19: =IFERROR(SUMIFS('Sunglasses BOM'!$E:$E, 'Sunglasses BOM'!$F:$F,"ABS", 'Sunglasses BOM'!$V:$V,$A19),0) -> 16800 | E19: 3.8 | F19: 6.4 | G19: =((F19*D19)+(E19*C19))/1000 -> 235.2 | H19: =G19*0.02 -> 4.704 | I19: =IFERROR(2*SUMIFS('Sunglasses BOM'!$E:$E, 'Sunglasses BOM'!$F:$F,"Clear ABS", 'Sunglasses BOM'!$W:$W,$A19),0) -> 0 | J19: =IFERROR(SUMIFS('Sunglasses BOM'!$E:$E, 'Sunglasses BOM'!$F:$F,"Clear ABS", 'Sunglasses BOM'!$V:$V,$A19),0) -> 0 | K19: =(J19*F19)+(I19*E19) -> 0 | L19: 2.95 | M19: 7.4 | N19: =IFERROR(2*SUMIFS('Sunglasses BOM'!$E:$E, 'Sunglasses BOM'!$F:$F,"PP", 'Sunglasses BOM'!$W:$W,$A19),0) -> 0 | O19: =IFERROR(SUMIFS('Sunglasses BOM'!$E:$E, 'Sunglasses BOM'!$F:$F,"PP", 'Sunglasses BOM'!$V:$V,$A19),0) -> 0 | P19: =((O19*M19)+(N19*L19))/1000 -> 0 | Q19: =P19*0.02 -> 0
A20: Black C | B20: =_xlfn.XLOOKUP(A20,'Sunglasses BOM'!$W$7:$W$76,'Sunglasses BOM'!$K$7:$K$76) -> Black | C20: =IFERROR(2*SUMIFS('Sunglasses BOM'!$E:$E, 'Sunglasses BOM'!$F:$F,"ABS", 'Sunglasses BOM'!$W:$W,$A20),0) -> 0 | D20: =IFERROR(SUMIFS('Sunglasses BOM'!$E:$E, 'Sunglasses BOM'!$F:$F,"ABS", 'Sunglasses BOM'!$V:$V,$A20),0) -> 0 | E20: 0 | F20: 0 | G20: =((F20*D20)+(E20*C20))/1000 -> 0 | H20: =G20*0.02 -> 0 | I20: =IFERROR(2*SUMIFS('Sunglasses BOM'!$E:$E, 'Sunglasses BOM'!$F:$F,"Clear ABS", 'Sunglasses BOM'!$W:$W,$A20),0) -> 0 | J20: =IFERROR(SUMIFS('Sunglasses BOM'!$E:$E, 'Sunglasses BOM'!$F:$F,"Clear ABS", 'Sunglasses BOM'!$V:$V,$A20),0) -> 0 | K20: =(J20*F20)+(I20*E20) -> 0 | L20: 2.95 | M20: 7.4 | N20: =IFERROR(2*SUMIFS('Sunglasses BOM'!$E:$E, 'Sunglasses BOM'!$F:$F,"PP", 'Sunglasses BOM'!$W:$W,$A20),0) -> 268800 | O20: =IFERROR(SUMIFS('Sunglasses BOM'!$E:$E, 'Sunglasses BOM'!$F:$F,"PP", 'Sunglasses BOM'!$V:$V,$A20),0) -> 159600 | P20: =((O20*M20)+(N20*L20))/1000 -> 1974 | Q20: =P20*0.02 -> 39.48
A21: 2144C | B21: =_xlfn.XLOOKUP(A21,'Sunglasses BOM'!$W$7:$W$76,'Sunglasses BOM'!$K$7:$K$76) -> Blue | C21: =IFERROR(2*SUMIFS('Sunglasses BOM'!$E:$E, 'Sunglasses BOM'!$F:$F,"ABS", 'Sunglasses BOM'!$W:$W,$A21),0) -> 0 | D21: =IFERROR(SUMIFS('Sunglasses BOM'!$E:$E, 'Sunglasses BOM'!$F:$F,"ABS", 'Sunglasses BOM'!$V:$V,$A21),0) -> 0 | E21: 0 | F21: 0 | G21: =((F21*D21)+(E21*C21))/1000 -> 0 | H21: =G21*0.02 -> 0 | I21: =IFERROR(2*SUMIFS('Sunglasses BOM'!$E:$E, 'Sunglasses BOM'!$F:$F,"Clear ABS", 'Sunglasses BOM'!$W:$W,$A21),0) -> 0 | J21: =IFERROR(SUMIFS('Sunglasses BOM'!$E:$E, 'Sunglasses BOM'!$F:$F,"Clear ABS", 'Sunglasses BOM'!$V:$V,$A21),0) -> 0 | K21: =(J21*F21)+(I21*E21) -> 0 | L21: 2.95 | M21: 7.4 | N21: =IFERROR(2*SUMIFS('Sunglasses BOM'!$E:$E, 'Sunglasses BOM'!$F:$F,"PP", 'Sunglasses BOM'!$W:$W,$A21),0) -> 336000 | O21: =IFERROR(SUMIFS('Sunglasses BOM'!$E:$E, 'Sunglasses BOM'!$F:$F,"PP", 'Sunglasses BOM'!$V:$V,$A21),0) -> 109200 | P21: =((O21*M21)+(N21*L21))/1000 -> 1799.28 | Q21: =P21*0.02 -> 35.9856
A22: 2270C | B22: =_xlfn.XLOOKUP(A22,'Sunglasses BOM'!$W$7:$W$76,'Sunglasses BOM'!$K$7:$K$76) -> Green | C22: =IFERROR(2*SUMIFS('Sunglasses BOM'!$E:$E, 'Sunglasses BOM'!$F:$F,"ABS", 'Sunglasses BOM'!$W:$W,$A22),0) -> 0 | D22: =IFERROR(SUMIFS('Sunglasses BOM'!$E:$E, 'Sunglasses BOM'!$F:$F,"ABS", 'Sunglasses BOM'!$V:$V,$A22),0) -> 0 | E22: 0 | F22: 0 | G22: =((F22*D22)+(E22*C22))/1000 -> 0 | H22: =G22*0.02 -> 0 | I22: =IFERROR(2*SUMIFS('Sunglasses BOM'!$E:$E, 'Sunglasses BOM'!$F:$F,"Clear ABS", 'Sunglasses BOM'!$W:$W,$A22),0) -> 0 | J22: =IFERROR(SUMIFS('Sunglasses BOM'!$E:$E, 'Sunglasses BOM'!$F:$F,"Clear ABS", 'Sunglasses BOM'!$V:$V,$A22),0) -> 0 | K22: =(J22*F22)+(I22*E22) -> 0 | L22: 2.95 | M22: 7.4 | N22: =IFERROR(2*SUMIFS('Sunglasses BOM'!$E:$E, 'Sunglasses BOM'!$F:$F,"PP", 'Sunglasses BOM'!$W:$W,$A22),0) -> 100800 | O22: =IFERROR(SUMIFS('Sunglasses BOM'!$E:$E, 'Sunglasses BOM'!$F:$F,"PP", 'Sunglasses BOM'!$V:$V,$A22),0) -> 50400 | P22: =((O22*M22)+(N22*L22))/1000 -> 670.32 | Q22: =P22*0.02 -> 13.4064
A23: 7628C | B23: =_xlfn.XLOOKUP(A23,'Sunglasses BOM'!$W$7:$W$76,'Sunglasses BOM'!$K$7:$K$76) -> Red | C23: =IFERROR(2*SUMIFS('Sunglasses BOM'!$E:$E, 'Sunglasses BOM'!$F:$F,"ABS", 'Sunglasses BOM'!$W:$W,$A23),0) -> 0 | D23: =IFERROR(SUMIFS('Sunglasses BOM'!$E:$E, 'Sunglasses BOM'!$F:$F,"ABS", 'Sunglasses BOM'!$V:$V,$A23),0) -> 0 | E23: 0 | F23: 0 | G23: =((F23*D23)+(E23*C23))/1000 -> 0 | H23: =G23*0.02 -> 0 | I23: =IFERROR(2*SUMIFS('Sunglasses BOM'!$E:$E, 'Sunglasses BOM'!$F:$F,"Clear ABS", 'Sunglasses BOM'!$W:$W,$A23),0) -> 0 | J23: =IFERROR(SUMIFS('Sunglasses BOM'!$E:$E, 'Sunglasses BOM'!$F:$F,"Clear ABS", 'Sunglasses BOM'!$V:$V,$A23),0) -> 0 | K23: =(J23*F23)+(I23*E23) -> 0 | L23: 2.95 | M23: 7.4 | N23: =IFERROR(2*SUMIFS('Sunglasses BOM'!$E:$E, 'Sunglasses BOM'!$F:$F,"PP", 'Sunglasses BOM'!$W:$W,$A23),0) -> 201600 | O23: =IFERROR(SUMIFS('Sunglasses BOM'!$E:$E, 'Sunglasses BOM'!$F:$F,"PP", 'Sunglasses BOM'!$V:$V,$A23),0) -> 84000 | P23: =((O23*M23)+(N23*L23))/1000 -> 1216.32 | Q23: =P23*0.02 -> 24.3264
A24: 423C | B24: =_xlfn.XLOOKUP(A24,'Sunglasses BOM'!$W$7:$W$76,'Sunglasses BOM'!$K$7:$K$76) -> Grey | C24: =IFERROR(2*SUMIFS('Sunglasses BOM'!$E:$E, 'Sunglasses BOM'!$F:$F,"ABS", 'Sunglasses BOM'!$W:$W,$A24),0) -> 0 | D24: =IFERROR(SUMIFS('Sunglasses BOM'!$E:$E, 'Sunglasses BOM'!$F:$F,"ABS", 'Sunglasses BOM'!$V:$V,$A24),0) -> 0 | E24: 0 | F24: 0 | G24: =((F24*D24)+(E24*C24))/1000 -> 0 | H24: =G24*0.02 -> 0 | I24: =IFERROR(2*SUMIFS('Sunglasses BOM'!$E:$E, 'Sunglasses BOM'!$F:$F,"Clear ABS", 'Sunglasses BOM'!$W:$W,$A24),0) -> 0 | J24: =IFERROR(SUMIFS('Sunglasses BOM'!$E:$E, 'Sunglasses BOM'!$F:$F,"Clear ABS", 'Sunglasses BOM'!$V:$V,$A24),0) -> 0 | K24: =(J24*F24)+(I24*E24) -> 0 | L24: 2.95 | M24: 7.4 | N24: =IFERROR(2*SUMIFS('Sunglasses BOM'!$E:$E, 'Sunglasses BOM'!$F:$F,"PP", 'Sunglasses BOM'!$W:$W,$A24),0) -> 16800 | O24: =IFERROR(SUMIFS('Sunglasses BOM'!$E:$E, 'Sunglasses BOM'!$F:$F,"PP", 'Sunglasses BOM'!$V:$V,$A24),0) -> 0 | P24: =((O24*M24)+(N24*L24))/1000 -> 49.56 | Q24: =P24*0.02 -> 0.9912
A25: 7428C | B25: =_xlfn.XLOOKUP(A25,'Sunglasses BOM'!$W$7:$W$76,'Sunglasses BOM'!$K$7:$K$76) -> Mar | C25: =IFERROR(2*SUMIFS('Sunglasses BOM'!$E:$E, 'Sunglasses BOM'!$F:$F,"ABS", 'Sunglasses BOM'!$W:$W,$A25),0) -> 0 | D25: =IFERROR(SUMIFS('Sunglasses BOM'!$E:$E, 'Sunglasses BOM'!$F:$F,"ABS", 'Sunglasses BOM'!$V:$V,$A25),0) -> 0 | E25: 0 | F25: 0 | G25: =((F25*D25)+(E25*C25))/1000 -> 0 | H25: =G25*0.02 -> 0 | I25: =IFERROR(2*SUMIFS('Sunglasses BOM'!$E:$E, 'Sunglasses BOM'!$F:$F,"Clear ABS", 'Sunglasses BOM'!$W:$W,$A25),0) -> 0 | J25: =IFERROR(SUMIFS('Sunglasses BOM'!$E:$E, 'Sunglasses BOM'!$F:$F,"Clear ABS", 'Sunglasses BOM'!$V:$V,$A25),0) -> 0 | K25: =(J25*F25)+(I25*E25) -> 0 | L25: 2.95 | M25: 7.4 | N25: =IFERROR(2*SUMIFS('Sunglasses BOM'!$E:$E, 'Sunglasses BOM'!$F:$F,"PP", 'Sunglasses BOM'!$W:$W,$A25),0) -> 16800 | O25: =IFERROR(SUMIFS('Sunglasses BOM'!$E:$E, 'Sunglasses BOM'!$F:$F,"PP", 'Sunglasses BOM'!$V:$V,$A25),0) -> 8400 | P25: =((O25*M25)+(N25*L25))/1000 -> 111.72 | Q25: =P25*0.02 -> 2.2344
A26: 1645C | B26: =_xlfn.XLOOKUP(A26,'Sunglasses BOM'!$W$7:$W$76,'Sunglasses BOM'!$K$7:$K$76) -> Orange | C26: =IFERROR(2*SUMIFS('Sunglasses BOM'!$E:$E, 'Sunglasses BOM'!$F:$F,"ABS", 'Sunglasses BOM'!$W:$W,$A26),0) -> 0 | D26: =IFERROR(SUMIFS('Sunglasses BOM'!$E:$E, 'Sunglasses BOM'!$F:$F,"ABS", 'Sunglasses BOM'!$V:$V,$A26),0) -> 0 | E26: 0 | F26: 0 | G26: =((F26*D26)+(E26*C26))/1000 -> 0 | H26: =G26*0.02 -> 0 | I26: =IFERROR(2*SUMIFS('Sunglasses BOM'!$E:$E, 'Sunglasses BOM'!$F:$F,"Clear ABS", 'Sunglasses BOM'!$W:$W,$A26),0) -> 0 | J26: =IFERROR(SUMIFS('Sunglasses BOM'!$E:$E, 'Sunglasses BOM'!$F:$F,"Clear ABS", 'Sunglasses BOM'!$V:$V,$A26),0) -> 0 | K26: =(J26*F26)+(I26*E26) -> 0 | L26: 2.95 | M26: 7.4 | N26: =IFERROR(2*SUMIFS('Sunglasses BOM'!$E:$E, 'Sunglasses BOM'!$F:$F,"PP", 'Sunglasses BOM'!$W:$W,$A26),0) -> 100800 | O26: =IFERROR(SUMIFS('Sunglasses BOM'!$E:$E, 'Sunglasses BOM'!$F:$F,"PP", 'Sunglasses BOM'!$V:$V,$A26),0) -> 50400 | P26: =((O26*M26)+(N26*L26))/1000 -> 670.32 | Q26: =P26*0.02 -> 13.4064
A27: 267C | B27: =_xlfn.XLOOKUP(A27,'Sunglasses BOM'!$W$7:$W$76,'Sunglasses BOM'!$K$7:$K$76) -> Purple | C27: =IFERROR(2*SUMIFS('Sunglasses BOM'!$E:$E, 'Sunglasses BOM'!$F:$F,"ABS", 'Sunglasses BOM'!$W:$W,$A27),0) -> 0 | D27: =IFERROR(SUMIFS('Sunglasses BOM'!$E:$E, 'Sunglasses BOM'!$F:$F,"ABS", 'Sunglasses BOM'!$V:$V,$A27),0) -> 0 | E27: 0 | F27: 0 | G27: =((F27*D27)+(E27*C27))/1000 -> 0 | H27: =G27*0.02 -> 0 | I27: =IFERROR(2*SUMIFS('Sunglasses BOM'!$E:$E, 'Sunglasses BOM'!$F:$F,"Clear ABS", 'Sunglasses BOM'!$W:$W,$A27),0) -> 0 | J27: =IFERROR(SUMIFS('Sunglasses BOM'!$E:$E, 'Sunglasses BOM'!$F:$F,"Clear ABS", 'Sunglasses BOM'!$V:$V,$A27),0) -> 0 | K27: =(J27*F27)+(I27*E27) -> 0 | L27: 2.95 | M27: 7.4 | N27: =IFERROR(2*SUMIFS('Sunglasses BOM'!$E:$E, 'Sunglasses BOM'!$F:$F,"PP", 'Sunglasses BOM'!$W:$W,$A27),0) -> 50400 | O27: =IFERROR(SUMIFS('Sunglasses BOM'!$E:$E, 'Sunglasses BOM'!$F:$F,"PP", 'Sunglasses BOM'!$V:$V,$A27),0) -> 25200 | P27: =((O27*M27)+(N27*L27))/1000 -> 335.16 | Q27: =P27*0.02 -> 6.7032
A28: 2174c | B28: =_xlfn.XLOOKUP(A28,'Sunglasses BOM'!$X$7:$X$76,'Sunglasses BOM'!$L$7:$L$76) -> Blue | C28: =IFERROR(2*SUMIFS('Sunglasses BOM'!$E:$E, 'Sunglasses BOM'!$F:$F,"ABS", 'Sunglasses BOM'!$W:$W,$A28),0) -> 0 | D28: =IFERROR(SUMIFS('Sunglasses BOM'!$E:$E, 'Sunglasses BOM'!$F:$F,"ABS", 'Sunglasses BOM'!$V:$V,$A28),0) -> 0 | E28: 0 | F28: 0 | G28: =((F28*D28)+(E28*C28))/1000 -> 0 | H28: =G28*0.02 -> 0 | I28: =IFERROR(2*SUMIFS('Sunglasses BOM'!$E:$E, 'Sunglasses BOM'!$F:$F,"Clear ABS", 'Sunglasses BOM'!$W:$W,$A28),0) -> 0 | J28: =IFERROR(SUMIFS('Sunglasses BOM'!$E:$E, 'Sunglasses BOM'!$F:$F,"Clear ABS", 'Sunglasses BOM'!$V:$V,$A28),0) -> 0 | K28: =(J28*F28)+(I28*E28) -> 0 | L28: 2.95 | M28: 7.4 | N28: =IFERROR(2*SUMIFS('Sunglasses BOM'!$E:$E, 'Sunglasses BOM'!$F:$F,"PP", 'Sunglasses BOM'!$W:$W,$A28),0) -> 0 | O28: =IFERROR(SUMIFS('Sunglasses BOM'!$E:$E, 'Sunglasses BOM'!$F:$F,"PP", 'Sunglasses BOM'!$V:$V,$A28),0) -> 8400 | P28: =((O28*M28)+(N28*L28))/1000 -> 62.16 | Q28: =P28*0.02 -> 1.2432
G29: =SUM(G4:G28) -> 13171.2 | H29: =SUM(H4:H28) -> 263.424 | I29: =SUM(I4:I28) -> 235200 | J29: =SUM(J4:J28) -> 117600 | K29: =SUM(K4:K28) -> 1646.4 | N29: =SUM(N4:N28) -> 1495200 | O29: =SUM(O4:O28) -> 747600 | P29: =SUM(P4:P28) -> 9943.08 | Q29: =SUM(Q4:Q28) -> 198.8616

Sheet Paint requirement
A1: Pantone Code | B1: No. of Painted parts | C1: Paint required (KG) | D1: Lacquer Required (1:1 for paint) | E1: Thinner
A2: Black 6C | B2: 109200 | C2: =(B2*0.8)/1000 -> 87.36 | D2: 87.36 | E2: =D2*2 -> 174.72
A3: White | B3: 33600 | C3: =(B3*0.8)/1000 -> 26.88 | D3: 26.88 | E3: =D3*2 -> 53.76
A5: lacquer (kg) | B5: 700 | C5: =B5*1400 -> 980000 | D5: =C5/1058200 -> 0.92610093
A6: Thinner (litre) | B6: 230

Sheet Mold Daily Output
A1: PP
A2: Frame
A3: mold no. | B3: Cavity | C3: Cycle time | D3: No. of Pieces | E3: is set | F3: output per day | G3: per minute | H3: per hour | I3: per day
A4: 7029-1 | B4: 2 | C4: 25 | D4: =B4 -> 2 | E4: 1 | F4: =I4/E4 -> 6336 | G4: =(60*D4)/C4 -> 4.8 | H4: =G4*60 -> 288 | I4: =H4*22 -> 6336
A5: 7030-1 | B5: 4 | C5: 33 | D5: =B5 -> 4 | E5: 1 | F5: =I5/E5 -> 9600 | G5: =(60*D5)/C5 -> 7.2727273 | H5: =G5*60 -> 436.36364 | I5: =H5*22 -> 9600
A6: 7031-1 | B6: 4 | C6: 33 | D6: =B6 -> 4 | E6: 1 | F6: =I6/E6 -> 9600 | G6: =(60*D6)/C6 -> 7.2727273 | H6: =G6*60 -> 436.36364 | I6: =H6*22 -> 9600
F7: =SUM(F4:F6) -> 25536
A8: Temple
A9: 7029-2 | B9: 4 | C9: 22 | D9: =B9 -> 4 | E9: 2 | F9: =I9/E9 -> 7200 | G9: =(60*D9)/C9 -> 10.909091 | H9: =G9*60 -> 654.54545 | I9: =H9*22 -> 14400
A10: 7030-2 | B10: 8 | C10: 33 | D10: =B10 -> 8 | E10: 2 | F10: =I10/E10 -> 9600 | G10: =(60*D10)/C10 -> 14.545455 | H10: =G10*60 -> 872.72727 | I10: =H10*22 -> 19200
A11: 7031-2 | B11: 8 | C11: 33 | D11: =B11 -> 8 | E11: 2 | F11: =I11/E11 -> 9600 | G11: =(60*D11)/C11 -> 14.545455 | H11: =G11*60 -> 872.72727 | I11: =H11*22 -> 19200
F12: =SUM(F9:F11) -> 26400
F13: `
A14: ABS
A15: Frame
A16: 7032-1 | B16: 2 | C16: 25 | D16: =B16 -> 2 | E16: 1 | F16: =I16/E16 -> 6336 | G16: =(60*D16)/C16 -> 4.8 | H16: =G16*60 -> 288 | I16: =H16*22 -> 6336
A17: 7033-1 | B17: 4 | C17: 30 | D17: =B17 -> 4 | E17: 1 | F17: =I17/E17 -> 10560 | G17: =(60*D17)/C17 -> 8 | H17: =G17*60 -> 480 | I17: =H17*22 -> 10560
A18: 7034-1 | B18: 4 | C18: 30 | D18: =B18 -> 4 | E18: 1 | F18: =I18/E18 -> 10560 | G18: =(60*D18)/C18 -> 8 | H18: =G18*60 -> 480 | I18: =H18*22 -> 10560
F19: =SUM(F16:F18) -> 27456
A20: Temple(value is for set, not a single piece)
A21: 7032-2 | B21: 4 | C21: 22 | D21: =B21 -> 4 | E21: 2 | F21: =I21/E21 -> 7200 | G21: =(60*D21)/C21 -> 10.909091 | H21: =G21*60 -> 654.54545 | I21: =H21*22 -> 14400
A22: 7033-2 | B22: 8 | C22: 30 | D22: =B22 -> 8 | E22: 2 | F22: =I22/E22 -> 10560 | G22: =(60*D22)/C22 -> 16 | H22: =G22*60 -> 960 | I22: =H22*22 -> 21120
A23: 7034-3 | B23: 8 | C23: 30 | D23: =B23 -> 8 | E23: 2 | F23: =I23/E23 -> 10560 | G23: =(60*D23)/C23 -> 16 | H23: =G23*60 -> 960 | I23: =H23*22 -> 21120
F24: =SUM(F21:F23) -> 28320

Sheet Molding ABS DPR
A1: Material | B1: ABS | H1: Day 1 | J1: Day 2 | L1: Day 3 | N1: Day 4 | P1: Day 5 | R1: Day 6 | T1: Day 7 | V1: Day 8 | X1: Day 9 | Z1: Day 10 | AB1: Day 11 | AD1: Day 12 | AF1: Day 13 | AH1: Day 14 | AJ1: Day 15 | AL1: Day 16 | AN1: Day 17 | AP1: Day 18 | AR1: Day 19 | AT1: Day 20 | AV1: Day 21 | AX1: Day 22 | AZ1: Day 23 | BB1: Day 24 | BD1: Day 25 | BF1: Day 26 | BH1: Day 27 | BJ1: Day 28 | BL1: Day 29 | BN1: Day 30 | BP1: Day 31 | BR1: Day 32 | BT1: Day 33 | BV1: Day 34 | BX1: Day 35 | BZ1: Day 36 | CB1: Day 37 | CD1: Day 38 | CF1: Day 39 | CH1: Day 40 | CJ1: Day 41 | CL1: Day 42 | CN1: Day 43 | CP1: Day 44 | CR1: Day 45 | CT1: Day 46 | CV1: Day 47 | CX1: Day 48 | CZ1: Day 49 | DB1: Day 50 | DD1: Day 51
A2: Mold | B2: 2 and 4 Cavity - Frame | C2: 3 Molds | H2: 45974 | J2: =WORKDAY.INTL(H2,1,"0010000") -> 45975 | L2: =WORKDAY.INTL(J2,1,"0010000") -> 45976 | N2: =WORKDAY.INTL(L2,1,"0010000") -> 45977 | P2: =WORKDAY.INTL(N2,1,"0010000") -> 45978 | R2: =WORKDAY.INTL(P2,1,"0010000") -> 45979 | T2: =WORKDAY.INTL(R2,1,"0010000") -> 45981 | V2: =WORKDAY.INTL(T2,1,"0010000") -> 45982 | X2: =WORKDAY.INTL(V2,1,"0010000") -> 45983 | Z2: =WORKDAY.INTL(X2,1,"0010000") -> 45984 | AB2: =WORKDAY.INTL(Z2,1,"0010000") -> 45985 | AD2: =WORKDAY.INTL(AB2,1,"0010000") -> 45986 | AF2: =WORKDAY.INTL(AD2,1,"0010000") -> 45988 | AH2: =WORKDAY.INTL(AF2,1,"0010000") -> 45989 | AJ2: =WORKDAY.INTL(AH2,1,"0010000") -> 45990 | AL2: =WORKDAY.INTL(AJ2,1,"0010000") -> 45991 | AN2: =WORKDAY.INTL(AL2,1,"0010000") -> 45992 | AP2: =WORKDAY.INTL(AN2,1,"0010000") -> 45993 | AR2: =WORKDAY.INTL(AP2,1,"0010000") -> 45995 | AT2: =WORKDAY.INTL(AR2,1,"0010000") -> 45996 | AV2: =WORKDAY.INTL(AT2,1,"0010000") -> 45997 | AX2: =WORKDAY.INTL(AV2,1,"0010000") -> 45998 | AZ2: =WORKDAY.INTL(AX2,1,"0010000") -> 45999 | BB2: =WORKDAY.INTL(AZ2,1,"0010000") -> 46000 | BD2: =WORKDAY.INTL(BB2,1,"0010000") -> 46002 | BF2: =WORKDAY.INTL(BD2,1,"0010000") -> 46003 | BH2: =WORKDAY.INTL(BF2,1,"0010000") -> 46004 | BJ2: =WORKDAY.INTL(BH2,1,"0010000") -> 46005 | BL2: =WORKDAY.INTL(BJ2,1,"0010000") -> 46006 | BN2: =WORKDAY.INTL(BL2,1,"0010000") -> 46007 | BP2: =WORKDAY.INTL(BN2,1,"0010000") -> 46009 | BR2: =WORKDAY.INTL(BP2,1,"0010000") -> 46010 | BT2: =WORKDAY.INTL(BR2,1,"0010000") -> 46011 | BV2: =WORKDAY.INTL(BT2,1,"0010000") -> 46012 | BX2: =WORKDAY.INTL(BV2,1,"0010000") -> 46013 | BZ2: =WORKDAY.INTL(BX2,1,"0010000") -> 46014 | CB2: =WORKDAY.INTL(BZ2,1,"0010000") -> 46016 | CD2: =WORKDAY.INTL(CB2,1,"0010000") -> 46017 | CF2: =WORKDAY.INTL(CD2,1,"0010000") -> 46018 | CH2: =WORKDAY.INTL(CF2,1,"0010000") -> 46019 | CJ2: =WORKDAY.INTL(CH2,1,"0010000") -> 46020 | CL2: =WORKDAY.INTL(CJ2,1,"0010000") -> 46021 | CN2: =WORKDAY.INTL(CL2,1,"0010000") -> 46023 | CP2: =WORKDAY.INTL(CN2,1,"0010000") -> 46024 | CR2: =WORKDAY.INTL(CP2,1,"0010000") -> 46025 | CT2: =WORKDAY.INTL(CR2,1,"0010000") -> 46026 | CV2: =WORKDAY.INTL(CT2,1,"0010000") -> 46027 | CX2: =WORKDAY.INTL(CV2,1,"0010000") -> 46028 | CZ2: =WORKDAY.INTL(CX2,1,"0010000") -> 46030 | DB2: =WORKDAY.INTL(CZ2,1,"0010000") -> 46031 | DD2: =WORKDAY.INTL(DB2,1,"0010000") -> 46032
A3: Pantone Code | B3: Color | C3: Order Qty | D3: Done Till Date | E3: Pending | F3: Daily Capacity | G3: Days required to complete | H3: Planned | I3: Actual | J3: Planned | K3: Actual | L3: Planned | M3: Actual | N3: Planned | O3: Actual | P3: Planned | Q3: Actual | R3: Planned | S3: Actual | T3: Planned | U3: Actual | V3: Planned | W3: Actual | X3: Planned | Y3: Actual | Z3: Planned | AA3: Actual | AB3: Planned | AC3: Actual | AD3: Planned | AE3: Actual | AF3: Planned | AG3: Actual | AH3: Planned | AI3: Actual | AJ3: Planned | AK3: Actual | AL3: Planned | AM3: Actual | AN3: Planned | AO3: Actual | AP3: Planned | AQ3: Actual | AR3: Planned | AS3: Actual | AT3: Planned | AU3: Actual | AV3: Planned | AW3: Actual | AX3: Planned | AY3: Actual | AZ3: Planned | BA3: Actual | BB3: Planned | BC3: Actual | BD3: Planned | BE3: Actual | BF3: Planned | BG3: Actual | BH3: Planned | BI3: Actual | BJ3: Planned | BK3: Actual | BL3: Planned | BM3: Actual | BN3: Planned | BO3: Actual | BP3: Planned | BQ3: Actual | BR3: Planned | BS3: Actual | BT3: Planned | BU3: Actual | BV3: Planned | BW3: Actual | BX3: Planned | BY3: Actual | BZ3: Planned | CA3: Actual | CB3: Planned | CC3: Actual | CD3: Planned | CE3: Actual | CF3: Planned | CG3: Actual | CH3: Planned | CI3: Actual | CJ3: Planned | CK3: Actual | CL3: Planned | CM3: Actual | CN3: Planned | CO3: Actual | CP3: Planned | CQ3: Actual | CR3: Planned | CS3: Actual | CT3: Planned | CU3: Actual | CV3: Planned | CW3: Actual | CX3: Planned | CY3: Actual | CZ3: Planned | DA3: Actual | DB3: Planned | DC3: Actual | DD3: Planned | DE3: Actual
A4: Black 6C | B4: =_xlfn.XLOOKUP(A4,'Raw Material Requirement'!$A$4:$A$28,'Raw Material Requirement'!$B$4:$B$28) -> Black | C4: =_xlfn.XLOOKUP(A4,'Raw Material Requirement'!$A$4:$A$28,'Raw Material Requirement'!$D$4:$D$28) -> 218400 | D4: {=SUMPRODUCT((MOD(COLUMN($I4:$FN4)-COLUMN($I4),2)=0)*($I4:$FN4))} -> 0 | E4: =C4-D4 -> 218400 | F4: ='Mold Daily Output'!$F$19 -> 27456 | G4: =E4/F4 -> 7.9545455 | H4: 27456 | J4: 27456 | L4: 27456 | N4: 27456 | P4: 27456 | R4: 27456 | T4: 27456 | V4: 26208
A5: 1807C | B5: =_xlfn.XLOOKUP(A5,'Raw Material Requirement'!$A$4:$A$28,'Raw Material Requirement'!$B$4:$B$28) -> Red | C5: =_xlfn.XLOOKUP(A5,'Raw Material Requirement'!$A$4:$A$28,'Raw Material Requirement'!$D$4:$D$28) -> 151200 | D5: {=SUMPRODUCT((MOD(COLUMN($I5:$FN5)-COLUMN($I5),2)=0)*($I5:$FN5))} -> 0 | E5: =C5-D5 -> 151200 | F5: ='Mold Daily Output'!$F$19 -> 27456 | G5: =E5/F5 -> 5.506993 | X5: 27456 | Z5: 27456 | AB5: 27456 | AD5: 27456 | AF5: 27456 | AH5: 13920
A6: WHITE | B6: =_xlfn.XLOOKUP(A6,'Raw Material Requirement'!$A$4:$A$28,'Raw Material Requirement'!$B$4:$B$28) -> White | C6: =_xlfn.XLOOKUP(A6,'Raw Material Requirement'!$A$4:$A$28,'Raw Material Requirement'!$D$4:$D$28) -> 134400 | D6: {=SUMPRODUCT((MOD(COLUMN($I6:$FN6)-COLUMN($I6),2)=0)*($I6:$FN6))} -> 0 | E6: =C6-D6 -> 134400 | F6: ='Mold Daily Output'!$F$19 -> 27456 | G6: =E6/F6 -> 4.8951049 | AJ6: 27456 | AL6: 27456 | AN6: 27456 | AP6: 27456 | AR6: 24576
A7: Clear | B7: =_xlfn.XLOOKUP(A7,'Raw Material Requirement'!$A$4:$A$28,'Raw Material Requirement'!$B$4:$B$28) -> Clear | C7: =_xlfn.XLOOKUP(A7,'Raw Material Requirement'!$A$4:$A$28,'Raw Material Requirement'!$J$4:$J$28) -> 117600 | D7: {=SUMPRODUCT((MOD(COLUMN($I7:$FN7)-COLUMN($I7),2)=0)*($I7:$FN7))} -> 0 | E7: =C7-D7 -> 117600 | F7: ='Mold Daily Output'!$F$19 -> 27456 | G7: =E7/F7 -> 4.2832168 | AT7: 27456 | AV7: 27456 | AX7: 27456 | AZ7: 27456 | BB7: 7776
A8: 648C | B8: =_xlfn.XLOOKUP(A8,'Raw Material Requirement'!$A$4:$A$28,'Raw Material Requirement'!$B$4:$B$28) -> Navy | C8: =_xlfn.XLOOKUP(A8,'Raw Material Requirement'!$A$4:$A$28,'Raw Material Requirement'!$D$4:$D$28) -> 100800 | D8: {=SUMPRODUCT((MOD(COLUMN($I8:$FN8)-COLUMN($I8),2)=0)*($I8:$FN8))} -> 0 | E8: =C8-D8 -> 100800 | F8: ='Mold Daily Output'!$F$19 -> 27456 | G8: =E8/F8 -> 3.6713287 | BD8: 27456 | BF8: 27456 | BH8: 27456 | BJ8: 18432
A9: 2746C | B9: =_xlfn.XLOOKUP(A9,'Raw Material Requirement'!$A$4:$A$28,'Raw Material Requirement'!$B$4:$B$28) -> Royal | C9: =_xlfn.XLOOKUP(A9,'Raw Material Requirement'!$A$4:$A$28,'Raw Material Requirement'!$D$4:$D$28) -> 100800 | D9: {=SUMPRODUCT((MOD(COLUMN($I9:$FN9)-COLUMN($I9),2)=0)*($I9:$FN9))} -> 0 | E9: =C9-D9 -> 100800 | F9: ='Mold Daily Output'!$F$19 -> 27456 | G9: =E9/F9 -> 3.6713287 | BJ9: 6000 | BL9: 27456 | BN9: 27456 | BP9: 27456 | BR9: 12432
A10: 2187C | B10: =_xlfn.XLOOKUP(A10,'Raw Material Requirement'!$A$4:$A$28,'Raw Material Requirement'!$B$4:$B$28) -> Blue | C10: =_xlfn.XLOOKUP(A10,'Raw Material Requirement'!$A$4:$A$28,'Raw Material Requirement'!$D$4:$D$28) -> 50400 | D10: {=SUMPRODUCT((MOD(COLUMN($I10:$FN10)-COLUMN($I10),2)=0)*($I10:$FN10))} -> 0 | E10: =C10-D10 -> 50400 | F10: ='Mold Daily Output'!$F$19 -> 27456 | G10: =E10/F10 -> 1.8356643 | BR10: 12000 | BT10: 27456 | BV10: 10944
A11: 201C | B11: =_xlfn.XLOOKUP(A11,'Raw Material Requirement'!$A$4:$A$28,'Raw Material Requirement'!$B$4:$B$28) -> Red | C11: =_xlfn.XLOOKUP(A11,'Raw Material Requirement'!$A$4:$A$28,'Raw Material Requirement'!$D$4:$D$28) -> 33600 | D11: {=SUMPRODUCT((MOD(COLUMN($I11:$FN11)-COLUMN($I11),2)=0)*($I11:$FN11))} -> 0 | E11: =C11-D11 -> 33600 | F11: ='Mold Daily Output'!$F$19 -> 27456 | G11: =E11/F11 -> 1.2237762 | BV11: 6144 | BX11: 27456
A12: 368C | B12: =_xlfn.XLOOKUP(A12,'Raw Material Requirement'!$A$4:$A$28,'Raw Material Requirement'!$B$4:$B$28) -> Lime | C12: =_xlfn.XLOOKUP(A12,'Raw Material Requirement'!$A$4:$A$28,'Raw Material Requirement'!$D$4:$D$28) -> 25200 | D12: {=SUMPRODUCT((MOD(COLUMN($I12:$FN12)-COLUMN($I12),2)=0)*($I12:$FN12))} -> 0 | E12: =C12-D12 -> 25200 | F12: ='Mold Daily Output'!$F$19 -> 27456 | G12: =E12/F12 -> 0.91783217 | BZ12: 25200
A13: 1655C | B13: =_xlfn.XLOOKUP(A13,'Raw Material Requirement'!$A$4:$A$28,'Raw Material Requirement'!$B$4:$B$28) -> Orange | C13: =_xlfn.XLOOKUP(A13,'Raw Material Requirement'!$A$4:$A$28,'Raw Material Requirement'!$D$4:$D$28) -> 25200 | D13: {=SUMPRODUCT((MOD(COLUMN($I13:$FN13)-COLUMN($I13),2)=0)*($I13:$FN13))} -> 0 | E13: =C13-D13 -> 25200 | F13: ='Mold Daily Output'!$F$19 -> 27456 | G13: =E13/F13 -> 0.91783217 | CB13: 25200
A14: 14-4318 TCX | B14: =_xlfn.XLOOKUP(A14,'Raw Material Requirement'!$A$4:$A$28,'Raw Material Requirement'!$B$4:$B$28) -> Light Blue | C14: =_xlfn.XLOOKUP(A14,'Raw Material Requirement'!$A$4:$A$28,'Raw Material Requirement'!$D$4:$D$28) -> 25200 | D14: {=SUMPRODUCT((MOD(COLUMN($I14:$FN14)-COLUMN($I14),2)=0)*($I14:$FN14))} -> 0 | E14: =C14-D14 -> 25200 | F14: ='Mold Daily Output'!$F$19 -> 27456 | G14: =E14/F14 -> 0.91783217 | CD14: 25200
A15: 7405C | B15: =_xlfn.XLOOKUP(A15,'Raw Material Requirement'!$A$4:$A$28,'Raw Material Requirement'!$B$4:$B$28) -> Bright Yellow | C15: =_xlfn.XLOOKUP(A15,'Raw Material Requirement'!$A$4:$A$28,'Raw Material Requirement'!$D$4:$D$28) -> 16800 | D15: {=SUMPRODUCT((MOD(COLUMN($I15:$FN15)-COLUMN($I15),2)=0)*($I15:$FN15))} -> 0 | E15: =C15-D15 -> 16800 | F15: ='Mold Daily Output'!$F$19 -> 27456 | G15: =E15/F15 -> 0.61188811 | CF15: 16800
A16: Cool Gray 8C | B16: =_xlfn.XLOOKUP(A16,'Raw Material Requirement'!$A$4:$A$28,'Raw Material Requirement'!$B$4:$B$28) -> Gray | C16: =_xlfn.XLOOKUP(A16,'Raw Material Requirement'!$A$4:$A$28,'Raw Material Requirement'!$D$4:$D$28) -> 16800 | D16: {=SUMPRODUCT((MOD(COLUMN($I16:$FN16)-COLUMN($I16),2)=0)*($I16:$FN16))} -> 0 | E16: =C16-D16 -> 16800 | F16: ='Mold Daily Output'!$F$19 -> 27456 | G16: =E16/F16 -> 0.61188811 | CF16: 9000 | CH16: 7800
A17: 342C | B17: =_xlfn.XLOOKUP(A17,'Raw Material Requirement'!$A$4:$A$28,'Raw Material Requirement'!$B$4:$B$28) -> Kelly Green | C17: =_xlfn.XLOOKUP(A17,'Raw Material Requirement'!$A$4:$A$28,'Raw Material Requirement'!$D$4:$D$28) -> 16800 | D17: {=SUMPRODUCT((MOD(COLUMN($I17:$FN17)-COLUMN($I17),2)=0)*($I17:$FN17))} -> 0 | E17: =C17-D17 -> 16800 | F17: ='Mold Daily Output'!$F$19 -> 27456 | G17: =E17/F17 -> 0.61188811 | CH17: 16800
A18: 2077C | B18: =_xlfn.XLOOKUP(A18,'Raw Material Requirement'!$A$4:$A$28,'Raw Material Requirement'!$B$4:$B$28) -> Purple | C18: =_xlfn.XLOOKUP(A18,'Raw Material Requirement'!$A$4:$A$28,'Raw Material Requirement'!$D$4:$D$28) -> 16800 | D18: {=SUMPRODUCT((MOD(COLUMN($I18:$FN18)-COLUMN($I18),2)=0)*($I18:$FN18))} -> 0 | E18: =C18-D18 -> 16800 | F18: ='Mold Daily Output'!$F$19 -> 27456 | G18: =E18/F18 -> 0.61188811 | BB18: 16800
A19: 107C | B19: =_xlfn.XLOOKUP(A19,'Raw Material Requirement'!$A$4:$A$28,'Raw Material Requirement'!$B$4:$B$28) -> Yellow | C19: =_xlfn.XLOOKUP(A19,'Raw Material Requirement'!$A$4:$A$28,'Raw Material Requirement'!$D$4:$D$28) -> 8400 | D19: {=SUMPRODUCT((MOD(COLUMN($I19:$FN19)-COLUMN($I19),2)=0)*($I19:$FN19))} -> 0 | E19: =C19-D19 -> 8400 | F19: ='Mold Daily Output'!$F$19 -> 27456 | G19: =E19/F19 -> 0.30594406 | AH19: 8400
G20: Raw Material Required (kg) | H20: =((SUM(H4:H19))*6.4)/1000 -> 175.7184 | I20: =((SUM(I4:I19))*6.4)/1000 -> 0 | J20: =((SUM(J4:J19))*6.4)/1000 -> 175.7184 | K20: =((SUM(K4:K19))*6.4)/1000 -> 0 | L20: =((SUM(L4:L19))*6.4)/1000 -> 175.7184 | M20: =((SUM(M4:M19))*6.4)/1000 -> 0 | N20: =((SUM(N4:N19))*6.4)/1000 -> 175.7184 | O20: =((SUM(O4:O19))*6.4)/1000 -> 0 | ... CI20: =((SUM(CI4:CI19))*6.4)/1000 -> 0
A23: Material | B23: ABS | H23: Day 1 | J23: Day 2 | L23: Day 3 | N23: Day 4 | P23: Day 5 | R23: Day 6 | T23: Day 7 | V23: Day 8 | X23: Day 9 | Z23: Day 10 | AB23: Day 11 | AD23: Day 12 | AF23: Day 13 | AH23: Day 14 | AJ23: Day 15 | AL23: Day 16 | AN23: Day 17 | AP23: Day 18 | AR23: Day 19 | AT23: Day 20 | AV23: Day 21 | AX23: Day 22 | AZ23: Day 23 | BB23: Day 24 | BD23: Day 25 | BF23: Day 26 | BH23: Day 27 | BJ23: Day 28 | BL23: Day 29 | BN23: Day 30 | BP23: Day 31 | BR23: Day 32 | BT23: Day 33 | BV23: Day 34 | BX23: Day 35 | BZ23: Day 36 | CB23: Day 37 | CD23: Day 38 | CF23: Day 39 | CH23: Day 40 | CJ23: Day 41 | CL23: Day 42 | CN23: Day 43 | CP23: Day 44 | CR23: Day 45 | CT23: Day 46 | CV23: Day 47 | CX23: Day 48 | CZ23: Day 49 | DB23: Day 50 | DD23: Day 51
A24: Mold | B24: 4 and 8 Cavity - Temple | C24: 3 Molds | H24: 45974 | J24: =WORKDAY.INTL(H24,1,"0010000") -> 45975 | L24: =WORKDAY.INTL(J24,1,"0010000") -> 45976 | N24: =WORKDAY.INTL(L24,1,"0010000") -> 45977 | P24: =WORKDAY.INTL(N24,1,"0010000") -> 45978 | R24: =WORKDAY.INTL(P24,1,"0010000") -> 45979 | T24: =WORKDAY.INTL(R24,1,"0010000") -> 45981 | V24: =WORKDAY.INTL(T24,1,"0010000") -> 45982 | X24: =WORKDAY.INTL(V24,1,"0010000") -> 45983 | Z24: =WORKDAY.INTL(X24,1,"0010000") -> 45984 | AB24: =WORKDAY.INTL(Z24,1,"0010000") -> 45985 | AD24: =WORKDAY.INTL(AB24,1,"0010000") -> 45986 | AF24: =WORKDAY.INTL(AD24,1,"0010000") -> 45988 | AH24: =WORKDAY.INTL(AF24,1,"0010000") -> 45989 | AJ24: =WORKDAY.INTL(AH24,1,"0010000") -> 45990 | AL24: =WORKDAY.INTL(AJ24,1,"0010000") -> 45991 | AN24: =WORKDAY.INTL(AL24,1,"0010000") -> 45992 | AP24: =WORKDAY.INTL(AN24,1,"0010000") -> 45993 | AR24: =WORKDAY.INTL(AP24,1,"0010000") -> 45995 | AT24: =WORKDAY.INTL(AR24,1,"0010000") -> 45996 | AV24: =WORKDAY.INTL(AT24,1,"0010000") -> 45997 | AX24: =WORKDAY.INTL(AV24,1,"0010000") -> 45998 | AZ24: =WORKDAY.INTL(AX24,1,"0010000") -> 45999 | BB24: =WORKDAY.INTL(AZ24,1,"0010000") -> 46000 | BD24: =WORKDAY.INTL(BB24,1,"0010000") -> 46002 | BF24: =WORKDAY.INTL(BD24,1,"0010000") -> 46003 | BH24: =WORKDAY.INTL(BF24,1,"0010000") -> 46004 | BJ24: =WORKDAY.INTL(BH24,1,"0010000") -> 46005 | BL24: =WORKDAY.INTL(BJ24,1,"0010000") -> 46006 | BN24: =WORKDAY.INTL(BL24,1,"0010000") -> 46007 | BP24: =WORKDAY.INTL(BN24,1,"0010000") -> 46009 | BR24: =WORKDAY.INTL(BP24,1,"0010000") -> 46010 | BT24: =WORKDAY.INTL(BR24,1,"0010000") -> 46011 | BV24: =WORKDAY.INTL(BT24,1,"0010000") -> 46012 | BX24: =WORKDAY.INTL(BV24,1,"0010000") -> 46013 | BZ24: =WORKDAY.INTL(BX24,1,"0010000") -> 46014 | CB24: =WORKDAY.INTL(BZ24,1,"0010000") -> 46016 | CD24: =WORKDAY.INTL(CB24,1,"0010000") -> 46017 | CF24: =WORKDAY.INTL(CD24,1,"0010000") -> 46018 | CH24: =WORKDAY.INTL(CF24,1,"0010000") -> 46019 | CJ24: =WORKDAY.INTL(CH24,1,"0010000") -> 46020 | CL24: =WORKDAY.INTL(CJ24,1,"0010000") -> 46021 | CN24: =WORKDAY.INTL(CL24,1,"0010000") -> 46023 | CP24: =WORKDAY.INTL(CN24,1,"0010000") -> 46024 | CR24: =WORKDAY.INTL(CP24,1,"0010000") -> 46025 | CT24: =WORKDAY.INTL(CR24,1,"0010000") -> 46026 | CV24: =WORKDAY.INTL(CT24,1,"0010000") -> 46027 | CX24: =WORKDAY.INTL(CV24,1,"0010000") -> 46028 | CZ24: =WORKDAY.INTL(CX24,1,"0010000") -> 46030 | DB24: =WORKDAY.INTL(CZ24,1,"0010000") -> 46031 | DD24: =WORKDAY.INTL(DB24,1,"0010000") -> 46032
A25: Pantone Code | B25: Color | C25: Order Qty | D25: Done Till Date | E25: Pending | F25: Daily Capacity (Each Piece) | G25: Days required to complete | H25: Planned | I25: Actual | J25: Planned | K25: Actual | L25: Planned | M25: Actual | N25: Planned | O25: Actual | P25: Planned | Q25: Actual | R25: Planned | S25: Actual | T25: Planned | U25: Actual | V25: Planned | W25: Actual | X25: Planned | Y25: Actual | Z25: Planned | AA25: Actual | AB25: Planned | AC25: Actual | AD25: Planned | AE25: Actual | AF25: Planned | AG25: Actual | AH25: Planned | AI25: Actual | AJ25: Planned | AK25: Actual | AL25: Planned | AM25: Actual | AN25: Planned | AO25: Actual | AP25: Planned | AQ25: Actual | AR25: Planned | AS25: Actual | AT25: Planned | AU25: Actual | AV25: Planned | AW25: Actual | AX25: Planned | AY25: Actual | AZ25: Planned | BA25: Actual | BB25: Planned | BC25: Actual | BD25: Planned | BE25: Actual | BF25: Planned | BG25: Actual | BH25: Planned | BI25: Actual | BJ25: Planned | BK25: Actual | BL25: Planned | BM25: Actual | BN25: Planned | BO25: Actual | BP25: Planned | BQ25: Actual | BR25: Planned | BS25: Actual | BT25: Planned | BU25: Actual | BV25: Planned | BW25: Actual | BX25: Planned | BY25: Actual | BZ25: Planned | CA25: Actual | CB25: Planned | CC25: Actual | CD25: Planned | CE25: Actual | CF25: Planned | CG25: Actual | CH25: Planned | CI25: Actual | CJ25: Planned | CK25: Actual | CL25: Planned | CM25: Actual | CN25: Planned | CO25: Actual | CP25: Planned | CQ25: Actual | CR25: Planned | CS25: Actual | CT25: Planned | CU25: Actual | CV25: Planned | CW25: Actual | CX25: Planned | CY25: Actual | CZ25: Planned | DA25: Actual | DB25: Planned | DC25: Actual | DD25: Planned | DE25: Actual
A26: Black 6C | B26: =_xlfn.XLOOKUP(A26,'Raw Material Requirement'!$A$4:$A$28,'Raw Material Requirement'!$B$4:$B$28) -> Black | C26: =_xlfn.XLOOKUP(A4,'Raw Material Requirement'!$A$4:$A$28,'Raw Material Requirement'!$C$4:$C$28) -> 436800 | D26: {=SUMPRODUCT((MOD(COLUMN($I26:$FN26)-COLUMN($I26),2)=0)*($I26:$FN26))} -> 0 | E26: =C26-D26 -> 436800 | F26: =('Mold Daily Output'!$F$24)*2 -> 56640 | G26: =E26/F26 -> 7.7118644 | H26: 56640 | J26: 56640 | L26: 56640 | N26: 56640 | P26: 56640 | R26: 56640 | T26: 56640 | V26: 40320
A27: 1807C | B27: =_xlfn.XLOOKUP(A27,'Raw Material Requirement'!$A$4:$A$28,'Raw Material Requirement'!$B$4:$B$28) -> Red | C27: =_xlfn.XLOOKUP(A5,'Raw Material Requirement'!$A$4:$A$28,'Raw Material Requirement'!$C$4:$C$28) -> 302400 | D27: {=SUMPRODUCT((MOD(COLUMN($I27:$FN27)-COLUMN($I27),2)=0)*($I27:$FN27))} -> 0 | E27: =C27-D27 -> 302400 | F27: =('Mold Daily Output'!$F$24)*2 -> 56640 | G27: =E27/F27 -> 5.3389831 | X27: 56640 | Z27: 56640 | AB27: 56640 | AD27: 56640 | AF27: 56640 | AH27: 19200
A28: WHITE | B28: =_xlfn.XLOOKUP(A28,'Raw Material Requirement'!$A$4:$A$28,'Raw Material Requirement'!$B$4:$B$28) -> White | C28: =_xlfn.XLOOKUP(A6,'Raw Material Requirement'!$A$4:$A$28,'Raw Material Requirement'!$C$4:$C$28) -> 268800 | D28: {=SUMPRODUCT((MOD(COLUMN($I28:$FN28)-COLUMN($I28),2)=0)*($I28:$FN28))} -> 0 | E28: =C28-D28 -> 268800 | F28: =('Mold Daily Output'!$F$24)*2 -> 56640 | G28: =E28/F28 -> 4.7457627 | AJ28: 56640 | AL28: 56640 | AN28: 56640 | AP28: 56640 | AR28: 42240
A29: Clear | B29: =_xlfn.XLOOKUP(A29,'Raw Material Requirement'!$A$4:$A$28,'Raw Material Requirement'!$B$4:$B$28) -> Clear | C29: =_xlfn.XLOOKUP(A7,'Raw Material Requirement'!$A$4:$A$28,'Raw Material Requirement'!$I$4:$I$28) -> 235200 | D29: {=SUMPRODUCT((MOD(COLUMN($I29:$FN29)-COLUMN($I29),2)=0)*($I29:$FN29))} -> 0 | E29: =C29-D29 -> 235200 | F29: =('Mold Daily Output'!$F$24)*2 -> 56640 | G29: =E29/F29 -> 4.1525424 | AT29: 56640 | AV29: 56640 | AX29: 56640 | AZ29: 56640 | BB29: 8640
A30: 648C | B30: =_xlfn.XLOOKUP(A30,'Raw Material Requirement'!$A$4:$A$28,'Raw Material Requirement'!$B$4:$B$28) -> Navy | C30: =_xlfn.XLOOKUP(A8,'Raw Material Requirement'!$A$4:$A$28,'Raw Material Requirement'!$C$4:$C$28) -> 201600 | D30: {=SUMPRODUCT((MOD(COLUMN($I30:$FN30)-COLUMN($I30),2)=0)*($I30:$FN30))} -> 0 | E30: =C30-D30 -> 201600 | F30: =('Mold Daily Output'!$F$24)*2 -> 56640 | G30: =E30/F30 -> 3.559322 | BD30: 56640 | BF30: 56640 | BH30: 56640 | BJ30: 31680
